Workbook

Sheet APRIL
A1: REKAPITULASI ABSENSI KEHADIRAN, APEL PAGI DAN APEL SIANG STAF UPTD. PKM ANGSAU
A2: DINAS / BADAN / KANTOR PUSKESMAS ANGSAU
A3: BULAN APRIL 2026
A4: NO | B4: NAMA | D4: PANGKAT / | E4: ST / S / F | F4: JABATAN | H4: 46113 | AL4: REKAP KEHADIRAN | AT4: KETERANGAN
D5: GOLONGAN | H5: 1 | I5: 2 | J5: 3 | K5: 4 | L5: 5 | M5: 6 | N5: 7 | O5: 8 | P5: 9 | Q5: 10 | R5: 11 | S5: 12 | T5: 13 | U5: 14 | V5: 15 | W5: 16 | X5: 17 | Y5: 18 | Z5: 19 | AA5: 20 | AB5: 21 | AC5: 22 | AD5: 23 | AE5: 24 | AF5: 25 | AG5: 26 | AH5: 27 | AI5: 28 | AJ5: 29 | AK5: 30 | AL5: H | AM5: S | AN5: I | AO5: C | AP5: DL | AQ5: CB | AR5: IB | AS5: TK
B6: KEHADIRAN
A7: 1 | B7: Iswati, S.ST | C7: 19691009 199011 2 001 | D7: Pembina Tk.I / IV.b | E7: ST | F7: Kepala UPTD Puskes Angsau | H7: H | I7: H | K7: H | M7: H | N7: H | O7: H | P7: H | Q7: H | R7: H | T7: H | U7: H | V7: H | W7: H | X7: H | Y7: H | AA7: H | AB7: H | AC7: H | AD7: H | AE7: H | AF7: H | AH7: H | AI7: H | AJ7: H | AK7: H | AL7: =COUNTIF(H7:AK7,"H") -> 25 | AM7: =COUNTIF(H7:AK7,"S") -> 0 | AN7: =COUNTIF(H7:AK7,"I") -> 0 | AO7: =COUNTIF(H7:AK7,"C") -> 0 | AP7: =COUNTIF(H7:AK7,"DL") -> 0 | AQ7: =COUNTIF(H7:AK7,"CB") -> 0 | AR7: =COUNTIF(H7:AK7,"IB") -> 0 | AS7: =COUNTIF(H7:AK7,"TK") -> 0
A8: 2 | B8: Anwar, S.Tr.Kes | C8: 19820619 200604 1 008 | D8: Penata / III.c | E8: ST | F8: Kasubbag TU | H8: H | I8: H | K8: H | M8: H | N8: H | O8: H | P8: H | Q8: H | R8: H | T8: H | U8: H | V8: H | W8: H | X8: H | Y8: H | AA8: H | AB8: H | AC8: H | AD8: H | AE8: H | AF8: H | AH8: H | AI8: H | AJ8: H | AK8: H | AL8: =COUNTIF(H8:AK8,"H") -> 25 | AM8: =COUNTIF(H8:AK8,"S") -> 0 | AN8: =COUNTIF(H8:AK8,"I") -> 0 | AO8: =COUNTIF(H8:AK8,"C") -> 0 | AP8: =COUNTIF(H8:AK8,"DL") -> 0 | AQ8: =COUNTIF(H8:AK8,"CB") -> 0 | AR8: =COUNTIF(H8:AK8,"IB") -> 0 | AS8: =COUNTIF(H8:AK8,"TK") -> 0
A9: 3 | B9: drg. Item Gandhi Wati | C9: 19801222 200903 2 007 | D9: Pembina Tk.I/ IV. b | E9: F | F9: Dokter Gigi Madya | H9: I | I9: H | K9: H | M9: H | N9: H | O9: H | P9: H | Q9: H | R9: H | T9: H | U9: H | V9: H | W9: H | X9: H | Y9: H | AA9: H | AB9: H | AC9: H | AD9: H | AE9: H | AF9: H | AH9: H | AI9: H | AJ9: H | AK9: H | AL9: =COUNTIF(H9:AK9,"H") -> 24 | AM9: =COUNTIF(H9:AK9,"S") -> 0 | AN9: =COUNTIF(H9:AK9,"I") -> 1 | AO9: =COUNTIF(H9:AK9,"C") -> 0 | AP9: =COUNTIF(H9:AK9,"DL") -> 0 | AQ9: =COUNTIF(H9:AK9,"CB") -> 0 | AR9: =COUNTIF(H9:AK9,"IB") -> 0 | AS9: =COUNTIF(H9:AK9,"TK") -> 0
A10: 4 | B10: drg. Diana Susanti | C10: 19780910 200604 2 026 | D10: Pembina Tk.I/ IV. b | E10: F | F10: Dokter Gigi Madya | H10: H | I10: H | K10: H | M10: H | N10: H | O10: H | P10: H | Q10: H | R10: H | T10: H | U10: H | V10: H | W10: H | X10: H | Y10: H | AA10: H | AB10: H | AC10: H | AD10: H | AE10: H | AF10: S | AH10: H | AI10: H | AJ10: H | AK10: H | AL10: =COUNTIF(H10:AK10,"H") -> 24 | AM10: =COUNTIF(H10:AK10,"S") -> 1 | AN10: =COUNTIF(H10:AK10,"I") -> 0 | AO10: =COUNTIF(H10:AK10,"C") -> 0 | AP10: =COUNTIF(H10:AK10,"DL") -> 0 | AQ10: =COUNTIF(H10:AK10,"CB") -> 0 | AR10: =COUNTIF(H10:AK10,"IB") -> 0 | AS10: =COUNTIF(H10:AK10,"TK") -> 0
A11: 5 | B11: dr. Mariatul Kiptiah | C11: 19800630 200903 2 009 | D11: Pembina / IV. a | E11: F | F11: Dokter Madya | H11: H | I11: H | K11: H | M11: DL | N11: H | O11: H | P11: H | Q11: H | R11: H | T11: H | U11: DL | V11: H | W11: H | X11: H | Y11: H | AA11: H | AB11: H | AC11: H | AD11: I | AE11: H | AF11: H | AH11: H | AI11: H | AJ11: H | AK11: H | AL11: =COUNTIF(H11:AK11,"H") -> 22 | AM11: =COUNTIF(H11:AK11,"S") -> 0 | AN11: =COUNTIF(H11:AK11,"I") -> 1 | AO11: =COUNTIF(H11:AK11,"C") -> 0 | AP11: =COUNTIF(H11:AK11,"DL") -> 2 | AQ11: =COUNTIF(H11:AK11,"CB") -> 0 | AR11: =COUNTIF(H11:AK11,"IB") -> 0 | AS11: =COUNTIF(H11:AK11,"TK") -> 0
A12: 6 | B12: dr. Yantari Tiyora | C12: 19920608 201903 2 011 | D12: Penata / III.c | E12: F | F12: Dokter Muda | H12: H | I12: H | K12: H | M12: H | N12: H | O12: H | P12: H | Q12: C | R12: C | T12: C | U12: C | V12: C | W12: C | X12: C | Y12: C | AA12: C | AB12: C | AC12: C | AD12: C | AE12: H | AF12: H | AH12: H | AI12: S | AJ12: H | AK12: H | AL12: =COUNTIF(H12:AK12,"H") -> 12 | AM12: =COUNTIF(H12:AK12,"S") -> 1 | AN12: =COUNTIF(H12:AK12,"I") -> 0 | AO12: =COUNTIF(H12:AK12,"C") -> 12 | AP12: =COUNTIF(H12:AK12,"DL") -> 0 | AQ12: =COUNTIF(H12:AK12,"CB") -> 0 | AR12: =COUNTIF(H12:AK12,"IB") -> 0 | AS12: =COUNTIF(H12:AK12,"TK") -> 0
A13: 7 | B13: Rahmiwati, A.Md.Kes,SKM | C13: 19710201 199402 0 003 | D13: Penata Tk.I / III.d | E13: F | F13: Terapis Gigi dan Mulut Penyelia | H13: H | I13: H | K13: H | M13: H | N13: H | O13: H | P13: H | Q13: H | R13: H | T13: H | U13: H | V13: H | W13: H | X13: H | Y13: H | AA13: H | AB13: H | AC13: H | AD13: H | AE13: H | AF13: H | AH13: H | AI13: H | AJ13: H | AK13: H | AL13: =COUNTIF(H13:AK13,"H") -> 25 | AM13: =COUNTIF(H13:AK13,"S") -> 0 | AN13: =COUNTIF(H13:AK13,"I") -> 0 | AO13: =COUNTIF(H13:AK13,"C") -> 0 | AP13: =COUNTIF(H13:AK13,"DL") -> 0 | AQ13: =COUNTIF(H13:AK13,"CB") -> 0 | AR13: =COUNTIF(H13:AK13,"IB") -> 0 | AS13: =COUNTIF(H13:AK13,"TK") -> 0
A14: 8 | B14: Rabiatul Adawiyah, AMd. Keb | C14: 19740626 199301 2 001 | D14: Penata Tk.I / III.d | E14: F | F14: Bidan Penyelia | H14: S | I14: H | K14: H | M14: H | N14: H | O14: S | P14: S | Q14: H | R14: H | T14: H | U14: H | V14: H | W14: H | X14: H | Y14: H | AA14: H | AB14: S | AC14: H | AD14: H | AE14: H | AF14: H | AH14: H | AI14: H | AJ14: H | AK14: H | AL14: =COUNTIF(H14:AK14,"H") -> 21 | AM14: =COUNTIF(H14:AK14,"S") -> 4 | AN14: =COUNTIF(H14:AK14,"I") -> 0 | AO14: =COUNTIF(H14:AK14,"C") -> 0 | AP14: =COUNTIF(H14:AK14,"DL") -> 0 | AQ14: =COUNTIF(H14:AK14,"CB") -> 0 | AR14: =COUNTIF(H14:AK14,"IB") -> 0 | AS14: =COUNTIF(H14:AK14,"TK") -> 0
A15: 9 | B15: Herlina Abdi,AMK | C15: 19781129 200604 2 012 | D15: Penata Tk.I / III.d | E15: F | F15: Perawat Penyelia | H15: DL | I15: H | K15: H | M15: DL | N15: H | O15: H | P15: H | Q15: H | R15: H | T15: H | U15: H | V15: H | W15: H | X15: H | Y15: H | AA15: H | AB15: H | AC15: H | AD15: H | AE15: H | AF15: H | AH15: H | AI15: H | AJ15: H | AK15: H | AL15: =COUNTIF(H15:AK15,"H") -> 23 | AM15: =COUNTIF(H15:AK15,"S") -> 0 | AN15: =COUNTIF(H15:AK15,"I") -> 0 | AO15: =COUNTIF(H15:AK15,"C") -> 0 | AP15: =COUNTIF(H15:AK15,"DL") -> 2 | AQ15: =COUNTIF(H15:AK15,"CB") -> 0 | AR15: =COUNTIF(H15:AK15,"IB") -> 0 | AS15: =COUNTIF(H15:AK15,"TK") -> 0
A16: 10 | B16: Erna Ningsih, S.Kep.,Ners | C16: 19811026 200604 2 012 | D16: Penata Tk.I / III.d | E16: F | F16: Perawat Ahli Muda | H16: H | I16: H | K16: H | M16: H | N16: H | O16: H | P16: H | Q16: H | R16: H | T16: H | U16: H | V16: H | W16: H | X16: H | Y16: H | AA16: H | AB16: H | AC16: H | AD16: H | AE16: H | AF16: H | AH16: H | AI16: H | AJ16: H | AK16: H | AL16: =COUNTIF(H16:AK16,"H") -> 25 | AM16: =COUNTIF(H16:AK16,"S") -> 0 | AN16: =COUNTIF(H16:AK16,"I") -> 0 | AO16: =COUNTIF(H16:AK16,"C") -> 0 | AP16: =COUNTIF(H16:AK16,"DL") -> 0 | AQ16: =COUNTIF(H16:AK16,"CB") -> 0 | AR16: =COUNTIF(H16:AK16,"IB") -> 0 | AS16: =COUNTIF(H16:AK16,"TK") -> 0
A17: 11 | B17: Fitriyani.AMK | C17: 19790815 200501 2 013 | D17: Penata Tk.I / III.d | E17: F | F17: Perawat Penyelia | H17: DL | I17: DL | K17: H | M17: H | N17: H | O17: H | P17: H | Q17: H | R17: H | T17: H | U17: H | V17: H | W17: DL | X17: I | Y17: H | AA17: H | AB17: H | AC17: H | AD17: H | AE17: H | AF17: H | AH17: H | AI17: H | AJ17: H | AK17: H | AL17: =COUNTIF(H17:AK17,"H") -> 21 | AM17: =COUNTIF(H17:AK17,"S") -> 0 | AN17: =COUNTIF(H17:AK17,"I") -> 1 | AO17: =COUNTIF(H17:AK17,"C") -> 0 | AP17: =COUNTIF(H17:AK17,"DL") -> 3 | AQ17: =COUNTIF(H17:AK17,"CB") -> 0 | AR17: =COUNTIF(H17:AK17,"IB") -> 0 | AS17: =COUNTIF(H17:AK17,"TK") -> 0
A18: 12 | B18: Syarifah Yartinah Alkaf,AMK | C18: 19840102 200903 2 010 | D18: Penata Tk.I / III.d | E18: F | F18: Perawat Penyelia | H18: H | I18: H | K18: H | M18: H | N18: H | O18: H | P18: H | Q18: DL | R18: H | T18: H | U18: H | V18: H | W18: H | X18: H | Y18: H | AA18: H | AB18: H | AC18: H | AD18: H | AE18: H | AF18: H | AH18: H | AI18: H | AJ18: H | AK18: H | AL18: =COUNTIF(H18:AK18,"H") -> 24 | AM18: =COUNTIF(H18:AK18,"S") -> 0 | AN18: =COUNTIF(H18:AK18,"I") -> 0 | AO18: =COUNTIF(H18:AK18,"C") -> 0 | AP18: =COUNTIF(H18:AK18,"DL") -> 1 | AQ18: =COUNTIF(H18:AK18,"CB") -> 0 | AR18: =COUNTIF(H18:AK18,"IB") -> 0 | AS18: =COUNTIF(H18:AK18,"TK") -> 0
... A43: 37 | B43: Rahmi Wulan Sari | C43: 19890809 202521 2 020 | D43: V | E43: F | F43: Pengadministrasian Perkantoran | H43: H | I43: H | K43: S | M43: H | N43: H | O43: H | P43: H | Q43: H | R43: H | T43: H | U43: H | V43: H | W43: H | X43: H | Y43: H | AA43: H | AB43: H | AC43: H | AD43: H | AE43: H | AF43: H | AH43: H | AI43: H | AJ43: H | AK43: H | AL43: =COUNTIF(H43:AK43,"H") -> 24 | AM43: =COUNTIF(H43:AK43,"S") -> 1 | AN43: =COUNTIF(H43:AK43,"I") -> 0 | AO43: =COUNTIF(H43:AK43,"C") -> 0 | AP43: =COUNTIF(H43:AK43,"DL") -> 0 | AQ43: =COUNTIF(H43:AK43,"CB") -> 0 | AR43: =COUNTIF(H43:AK43,"IB") -> 0 | AS43: =COUNTIF(H43:AK43,"TK") -> 0
A44: 38 | B44: Ida Nursanti, A.Mg | C44: 19850814 202521 2 048 | E44: G | F44: Nutrisionis Terampil | H44: H | I44: H | K44: H | M44: H | N44: H | O44: H | P44: H | Q44: H | R44: H | T44: H | U44: H | V44: H | W44: H | X44: H | Y44: I | AA44: H | AB44: H | AC44: H | AD44: I | AE44: H | AF44: H | AH44: H | AI44: H | AJ44: H | AK44: H | AL44: =COUNTIF(H44:AK44,"H") -> 23 | AM44: =COUNTIF(H44:AK44,"S") -> 0 | AN44: =COUNTIF(H44:AK44,"I") -> 2 | AO44: =COUNTIF(H44:AK44,"C") -> 0 | AP44: =COUNTIF(H44:AK44,"DL") -> 0 | AQ44: =COUNTIF(H44:AK44,"CB") -> 0 | AR44: =COUNTIF(H44:AK44,"IB") -> 0 | AS44: =COUNTIF(H44:AK44,"TK") -> 0
A45: 39 | B45: Rico Andrianto Utama,AMK | C45: 19900523 202521 1 064 | E45: G | F45: Perawat Terampil | H45: H | I45: H | K45: H | M45: H | N45: DL | O45: S | P45: H | Q45: H | R45: H | T45: H | U45: H | V45: H | W45: H | X45: H | Y45: H | AA45: I | AB45: H | AC45: H | AD45: H | AE45: H | AF45: H | AH45: H | AI45: S | AJ45: H | AK45: H | AL45: =COUNTIF(H45:AK45,"H") -> 21 | AM45: =COUNTIF(H45:AK45,"S") -> 2 | AN45: =COUNTIF(H45:AK45,"I") -> 1 | AO45: =COUNTIF(H45:AK45,"C") -> 0 | AP45: =COUNTIF(H45:AK45,"DL") -> 1 | AQ45: =COUNTIF(H45:AK45,"CB") -> 0 | AR45: =COUNTIF(H45:AK45,"IB") -> 0 | AS45: =COUNTIF(H45:AK45,"TK") -> 0
A46: 40 | B46: Laily Nur, S. Keb., Bdn | C46: 19890911 202521 2 055 | E46: G | F46: Bidan Ahli Pertama | H46: H | I46: H | K46: H | M46: H | N46: H | O46: H | P46: H | Q46: H | R46: H | T46: H | U46: H | V46: H | W46: H | X46: H | Y46: H | AA46: H | AB46: H | AC46: H | AD46: H | AE46: H | AF46: H | AH46: H | AI46: H | AJ46: H | AK46: H | AL46: =COUNTIF(H46:AK46,"H") -> 25 | AM46: =COUNTIF(H46:AK46,"S") -> 0 | AN46: =COUNTIF(H46:AK46,"I") -> 0 | AO46: =COUNTIF(H46:AK46,"C") -> 0 | AP46: =COUNTIF(H46:AK46,"DL") -> 0 | AQ46: =COUNTIF(H46:AK46,"CB") -> 0 | AR46: =COUNTIF(H46:AK46,"IB") -> 0 | AS46: =COUNTIF(H46:AK46,"TK") -> 0
A47: 41 | B47: Siti Rahmawati, Am.Keb | C47: 19870516 202521 2 060 | E47: G | F47: Bidan Terampil | H47: H | I47: H | K47: H | M47: H | N47: H | O47: H | P47: H | Q47: H | R47: H | T47: H | U47: H | V47: H | W47: H | X47: H | Y47: H | AA47: H | AB47: H | AC47: H | AD47: H | AE47: H | AF47: H | AH47: H | AI47: H | AJ47: H | AK47: H | AL47: =COUNTIF(H47:AK47,"H") -> 25 | AM47: =COUNTIF(H47:AK47,"S") -> 0 | AN47: =COUNTIF(H47:AK47,"I") -> 0 | AO47: =COUNTIF(H47:AK47,"C") -> 0 | AP47: =COUNTIF(H47:AK47,"DL") -> 0 | AQ47: =COUNTIF(H47:AK47,"CB") -> 0 | AR47: =COUNTIF(H47:AK47,"IB") -> 0 | AS47: =COUNTIF(H47:AK47,"TK") -> 0
A48: 42 | B48: Sheny Budiarti, S.Si.T | C48: 19930911 202521 2 075 | E48: G | F48: Bidan Ahli Pertama | H48: H | I48: H | K48: H | M48: H | N48: H | O48: H | P48: H | Q48: H | R48: H | T48: H | U48: H | V48: H | W48: H | X48: H | Y48: H | AA48: H | AB48: H | AC48: H | AD48: H | AE48: H | AF48: H | AH48: H | AI48: H | AJ48: H | AK48: H | AL48: =COUNTIF(H48:AK48,"H") -> 25 | AM48: =COUNTIF(H48:AK48,"S") -> 0 | AN48: =COUNTIF(H48:AK48,"I") -> 0 | AO48: =COUNTIF(H48:AK48,"C") -> 0 | AP48: =COUNTIF(H48:AK48,"DL") -> 0 | AQ48: =COUNTIF(H48:AK48,"CB") -> 0 | AR48: =COUNTIF(H48:AK48,"IB") -> 0 | AS48: =COUNTIF(H48:AK48,"TK") -> 0
A49: 43 | B49: Setia Rahayu, A.Md. Keb | C49: 19911011 202521 2 058 | E49: G | F49: Bidan Terampil | H49: H | I49: H | K49: H | M49: H | N49: H | O49: H | P49: H | Q49: H | R49: H | T49: H | U49: H | V49: H | W49: I | X49: H | Y49: H | AA49: H | AB49: H | AC49: I | AD49: H | AE49: H | AF49: H | AH49: H | AI49: H | AJ49: H | AK49: H | AL49: =COUNTIF(H49:AK49,"H") -> 23 | AM49: =COUNTIF(H49:AK49,"S") -> 0 | AN49: =COUNTIF(H49:AK49,"I") -> 2 | AO49: =COUNTIF(H49:AK49,"C") -> 0 | AP49: =COUNTIF(H49:AK49,"DL") -> 0 | AQ49: =COUNTIF(H49:AK49,"CB") -> 0 | AR49: =COUNTIF(H49:AK49,"IB") -> 0 | AS49: =COUNTIF(H49:AK49,"TK") -> 0
A50: 44 | B50: Eka Maulida Putri, A.Md.Keb | C50: 19940905 202521 2 064 | E50: G | F50: Bidan Terampil | H50: H | I50: H | K50: H | M50: H | N50: H | O50: H | P50: H | Q50: H | R50: H | T50: H | U50: I | V50: I | W50: I | X50: I | Y50: I | AA50: I | AB50: I | AC50: I | AD50: I | AE50: I | AF50: I | AH50: H | AI50: H | AJ50: H | AK50: H | AL50: =COUNTIF(H50:AK50,"H") -> 14 | AM50: =COUNTIF(H50:AK50,"S") -> 0 | AN50: =COUNTIF(H50:AK50,"I") -> 11 | AO50: =COUNTIF(H50:AK50,"C") -> 0 | AP50: =COUNTIF(H50:AK50,"DL") -> 0 | AQ50: =COUNTIF(H50:AK50,"CB") -> 0 | AR50: =COUNTIF(H50:AK50,"IB") -> 0 | AS50: =COUNTIF(H50:AK50,"TK") -> 0
A51: 45 | B51: Latipah | C51: 19890310 202521 2 096 | E51: G | F51: Operator Layanan Operasional | H51: H | I51: H | K51: H | M51: H | N51: H | O51: H | P51: H | Q51: H | R51: H | T51: H | U51: I | V51: H | W51: H | X51: H | Y51: H | AA51: H | AB51: H | AC51: S | AD51: H | AE51: H | AF51: H | AH51: H | AI51: H | AJ51: H | AK51: H | AL51: =COUNTIF(H51:AK51,"H") -> 23 | AM51: =COUNTIF(H51:AK51,"S") -> 1 | AN51: =COUNTIF(H51:AK51,"I") -> 1 | AO51: =COUNTIF(H51:AK51,"C") -> 0 | AP51: =COUNTIF(H51:AK51,"DL") -> 0 | AQ51: =COUNTIF(H51:AK51,"CB") -> 0 | AR51: =COUNTIF(H51:AK51,"IB") -> 0 | AS51: =COUNTIF(H51:AK51,"TK") -> 0
A52: 46 | B52: Agus Rahmat | C52: 19760804 202521 1 042 | E52: G | F52: Operator Layanan Operasional | H52: H | I52: H | K52: H | M52: H | N52: H | O52: H | P52: H | Q52: H | R52: H | T52: H | U52: H | V52: H | W52: H | X52: H | Y52: H | AA52: S | AB52: H | AC52: H | AD52: H | AE52: H | AF52: H | AH52: H | AI52: H | AJ52: H | AK52: H | AL52: =COUNTIF(H52:AK52,"H") -> 24 | AM52: =COUNTIF(H52:AK52,"S") -> 1 | AN52: =COUNTIF(H52:AK52,"I") -> 0 | AO52: =COUNTIF(H52:AK52,"C") -> 0 | AP52: =COUNTIF(H52:AK52,"DL") -> 0 | AQ52: =COUNTIF(H52:AK52,"CB") -> 0 | AR52: =COUNTIF(H52:AK52,"IB") -> 0 | AS52: =COUNTIF(H52:AK52,"TK") -> 0
A53: 47 | B53: Yudi Rahman | C53: 19910928 202521 1 047 | E53: G | F53: Operator Layanan Operasional | H53: H | I53: H | K53: H | M53: H | N53: H | O53: H | P53: H | Q53: H | R53: H | T53: H | U53: H | V53: H | W53: H | X53: H | Y53: H | AA53: H | AB53: H | AC53: H | AD53: H | AE53: H | AF53: H | AH53: H | AI53: H | AJ53: H | AK53: H | AL53: =COUNTIF(H53:AK53,"H") -> 25 | AM53: =COUNTIF(H53:AK53,"S") -> 0 | AN53: =COUNTIF(H53:AK53,"I") -> 0 | AO53: =COUNTIF(H53:AK53,"C") -> 0 | AP53: =COUNTIF(H53:AK53,"DL") -> 0 | AQ53: =COUNTIF(H53:AK53,"CB") -> 0 | AR53: =COUNTIF(H53:AK53,"IB") -> 0 | AS53: =COUNTIF(H53:AK53,"TK") -> 0
A54: 48 | B54: Yasirwan | C54: 19830322 202521 1 047 | E54: G | F54: Operator Layanan Operasional | H54: H | I54: H | K54: H | M54: H | N54: H | O54: H | P54: H | Q54: H | R54: H | T54: H | U54: H | V54: H | W54: H | X54: H | Y54: S | AA54: H | AB54: H | AC54: H | AD54: H | AE54: H | AF54: H | AH54: H | AI54: H | AJ54: H | AK54: H | AL54: =COUNTIF(H54:AK54,"H") -> 24 | AM54: =COUNTIF(H54:AK54,"S") -> 1 | AN54: =COUNTIF(H54:AK54,"I") -> 0 | AO54: =COUNTIF(H54:AK54,"C") -> 0 | AP54: =COUNTIF(H54:AK54,"DL") -> 0 | AQ54: =COUNTIF(H54:AK54,"CB") -> 0 | AR54: =COUNTIF(H54:AK54,"IB") -> 0 | AS54: =COUNTIF(H54:AK54,"TK") -> 0
A55: 49 | B55: Abdul Ghoni Zean, A.Md.Kom | C55: - | D55: PTT BLUD | E55: G | F55: Tenaga Teknologi Informasi | H55: H | I55: H | K55: H | M55: H | N55: H | O55: H | P55: H | Q55: H | R55: H | T55: H | U55: H | V55: H | W55: H | X55: H | Y55: H | AA55: H | AB55: H | AC55: H | AD55: H | AE55: H | AF55: H | AH55: H | AI55: H | AJ55: H | AK55: H | AL55: =COUNTIF(H55:AK55,"H") -> 25 | AM55: =COUNTIF(H55:AK55,"S") -> 0 | AN55: =COUNTIF(H55:AK55,"I") -> 0 | AO55: =COUNTIF(H55:AK55,"C") -> 0 | AP55: =COUNTIF(H55:AK55,"DL") -> 0 | AQ55: =COUNTIF(H55:AK55,"CB") -> 0 | AR55: =COUNTIF(H55:AK55,"IB") -> 0 | AS55: =COUNTIF(H55:AK55,"TK") -> 0
A56: 50 | B56: Salmiyah, A.Md.Ak | C56: - | D56: PTT BLUD | E56: G | F56: Tenaga Keuangan | H56: H | I56: H | K56: H | M56: H | N56: H | O56: H | P56: H | Q56: H | R56: H | T56: H | U56: H | V56: H | W56: H | X56: H | Y56: H | AA56: H | AB56: H | AC56: S | AD56: H | AE56: H | AF56: H | AH56: H | AI56: H | AJ56: H | AK56: H | AL56: =COUNTIF(H56:AK56,"H") -> 24 | AM56: =COUNTIF(H56:AK56,"S") -> 1 | AN56: =COUNTIF(H56:AK56,"I") -> 0 | AO56: =COUNTIF(H56:AK56,"C") -> 0 | AP56: =COUNTIF(H56:AK56,"DL") -> 0 | AQ56: =COUNTIF(H56:AK56,"CB") -> 0 | AR56: =COUNTIF(H56:AK56,"IB") -> 0 | AS56: =COUNTIF(H56:AK56,"TK") -> 0
AL57: Pelaihari, 31 Maret 2026
F58: Kepala Puskesmas Angsau | AL58: Pembuat Daftar
F62: Iswati, S.ST | AL62: Fera Wati, A.Md
F63: NIP.19691009 199011 2 001 | AL63: NIP. 19850907 2025212 018
B64: REKAPITULASI ABSENSI KEHADIRAN, APEL PAGI DAN APEL SIANG STAF UPTD. PKM ANGSAU
B65: DINAS / BADAN / KANTOR PUSKESMAS ANGSAU
B66: BULAN APRIL 2026
A67: NO | B67: NAMA | D67: PANGKAT / | E67: ST / S / F | F67: JABATAN | H67: 46113 | AL67: REKAP APEL PAGI | AT67: KETERANGAN
...

Sheet Rekap Bulanan
A2: NO | B2: NAMA | D2: PANGKAT / | E2: ST / S / F | F2: JABATAN | H2: REKAP KEHADIRAN | AF2: REKAP TIDAK APEL PAGI+ APEL SIANG
D3: GOLONGAN | G3: Januari | H3: 1 | I3: Pebruari | J3: 2 | K3: Maret | L3: 3 | M3: April | N3: 4 | O3: Mei | P3: 5 | Q3: Juni | R3: 6 | S3: Juli | T3: 7 | U3: Agustus | V3: 8 | W3: September | X3: 9 | Y3: Oktober | Z3: 10 | AA3: Nopember | AB3: 11 | AC3: Desember | AD3: 12 | AF3: 1 | AG3: 2 | AH3: 3 | AI3: 4 | AJ3: 5 | AK3: 6 | AL3: 7 | AM3: 8 | AN3: 9 | AO3: 10 | AP3: 11 | AQ3: 12
A5: 1 | B5: =#REF! -> #REF! | C5: =#REF! -> #REF! | D5: =#REF! -> #REF! | E5: =#REF! -> #REF! | F5: =#REF! -> #REF! | G5: =#REF! -> #REF! | I5: =#REF! -> #REF! | K5: =#REF! -> #REF! | M5: =#REF! -> #REF! | O5: =#REF! -> #REF! | Q5: =#REF! -> #REF! | S5: =#REF! -> #REF! | U5: =#REF! -> #REF! | W5: =#REF! -> #REF! | Y5: =#REF! -> #REF! | Z5: =#REF! -> #REF! | AA5: =#REF! -> #REF! | AB5: =#REF! -> #REF! | AC5: =#REF! -> #REF! | AD5: =#REF! -> #REF! | AF5: =#REF! -> #REF! | AG5: =#REF! -> #REF! | AH5: =#REF! -> #REF! | AI5: =#REF! -> #REF! | AJ5: =#REF! -> #REF! | AK5: =#REF! -> #REF!
A6: 2 | B6: =#REF! -> #REF! | C6: =#REF! -> #REF! | D6: =#REF! -> #REF! | E6: =#REF! -> #REF! | F6: =#REF! -> #REF! | G6: =#REF! -> #REF! | H6: =#REF! -> #REF! | I6: =#REF! -> #REF! | ... AD6: =#REF! -> #REF! | AF6: =#REF! -> #REF! | AG6: =#REF! -> #REF! | AH6: =#REF! -> #REF! | AI6: =#REF! -> #REF! | AJ6: =#REF! -> #REF! | AK6: =#REF! -> #REF!
A7: 3 | B7: =#REF! -> #REF! | C7: =#REF! -> #REF! | D7: =#REF! -> #REF! | E7: =#REF! -> #REF! | F7: =#REF! -> #REF! | G7: =#REF! -> #REF! | H7: =#REF! -> #REF! | I7: =#REF! -> #REF! | ... AD7: =#REF! -> #REF! | AF7: =#REF! -> #REF! | AG7: =#REF! -> #REF! | AH7: =#REF! -> #REF! | AI7: =#REF! -> #REF! | AJ7: =#REF! -> #REF! | AK7: =#REF! -> #REF!
A8: 4 | B8: =#REF! -> #REF! | C8: =#REF! -> #REF! | D8: =#REF! -> #REF! | E8: =#REF! -> #REF! | F8: =#REF! -> #REF! | G8: =#REF! -> #REF! | H8: =#REF! -> #REF! | I8: =#REF! -> #REF! | ... AD8: =#REF! -> #REF! | AF8: =#REF! -> #REF! | AG8: =#REF! -> #REF! | AH8: =#REF! -> #REF! | AI8: =#REF! -> #REF! | AJ8: =#REF! -> #REF! | AK8: =#REF! -> #REF!
A9: 5 | B9: =#REF! -> #REF! | C9: =#REF! -> #REF! | D9: =#REF! -> #REF! | E9: =#REF! -> #REF! | F9: =#REF! -> #REF! | G9: =#REF! -> #REF! | H9: =#REF! -> #REF! | I9: =#REF! -> #REF! | ... AD9: =#REF! -> #REF! | AF9: =#REF! -> #REF! | AG9: =#REF! -> #REF! | AH9: =#REF! -> #REF! | AI9: =#REF! -> #REF! | AJ9: =#REF! -> #REF! | AK9: =#REF! -> #REF!
A10: 6 | B10: =#REF! -> #REF! | C10: =#REF! -> #REF! | D10: =#REF! -> #REF! | E10: =#REF! -> #REF! | F10: =#REF! -> #REF! | G10: =#REF! -> #REF! | H10: =#REF! -> #REF! | I10: =#REF! -> #REF! | ... AD10: =#REF! -> #REF! | AF10: =#REF! -> #REF! | AG10: =#REF! -> #REF! | AH10: =#REF! -> #REF! | AI10: =#REF! -> #REF! | AJ10: =#REF! -> #REF! | AK10: =#REF! -> #REF!
A11: 7 | B11: =#REF! -> #REF! | C11: =#REF! -> #REF! | D11: =#REF! -> #REF! | E11: =#REF! -> #REF! | F11: =#REF! -> #REF! | G11: =#REF! -> #REF! | H11: =#REF! -> #REF! | I11: =#REF! -> #REF! | ... AD11: =#REF! -> #REF! | AF11: =#REF! -> #REF! | AG11: =#REF! -> #REF! | AH11: =#REF! -> #REF! | AI11: =#REF! -> #REF! | AJ11: =#REF! -> #REF! | AK11: =#REF! -> #REF!
A12: 8 | B12: =#REF! -> #REF! | C12: =#REF! -> #REF! | D12: =#REF! -> #REF! | E12: =#REF! -> #REF! | F12: =#REF! -> #REF! | G12: =#REF! -> #REF! | H12: =#REF! -> #REF! | I12: =#REF! -> #REF! | ... AD12: =#REF! -> #REF! | AF12: =#REF! -> #REF! | AG12: =#REF! -> #REF! | AH12: =#REF! -> #REF! | AI12: =#REF! -> #REF! | AJ12: =#REF! -> #REF! | AK12: =#REF! -> #REF!
A13: 9 | B13: =#REF! -> #REF! | C13: =#REF! -> #REF! | D13: =#REF! -> #REF! | E13: =#REF! -> #REF! | F13: =#REF! -> #REF! | G13: =#REF! -> #REF! | H13: =#REF! -> #REF! | I13: =#REF! -> #REF! | ... AD13: =#REF! -> #REF! | AF13: =#REF! -> #REF! | AG13: =#REF! -> #REF! | AH13: =#REF! -> #REF! | AI13: =#REF! -> #REF! | AJ13: =#REF! -> #REF! | AK13: =#REF! -> #REF!
A14: 10 | B14: =#REF! -> #REF! | C14: =#REF! -> #REF! | D14: =#REF! -> #REF! | E14: =#REF! -> #REF! | F14: =#REF! -> #REF! | G14: =#REF! -> #REF! | H14: =#REF! -> #REF! | I14: =#REF! -> #REF! | ... AD14: =#REF! -> #REF! | AF14: =#REF! -> #REF! | AG14: =#REF! -> #REF! | AH14: =#REF! -> #REF! | AI14: =#REF! -> #REF! | AJ14: =#REF! -> #REF! | AK14: =#REF! -> #REF!
A15: 11 | B15: =#REF! -> #REF! | C15: =#REF! -> #REF! | D15: =#REF! -> #REF! | E15: =#REF! -> #REF! | F15: =#REF! -> #REF! | G15: =#REF! -> #REF! | H15: =#REF! -> #REF! | I15: =#REF! -> #REF! | ... AD15: =#REF! -> #REF! | AF15: =#REF! -> #REF! | AG15: =#REF! -> #REF! | AH15: =#REF! -> #REF! | AI15: =#REF! -> #REF! | AJ15: =#REF! -> #REF! | AK15: =#REF! -> #REF!
A16: 12 | B16: =#REF! -> #REF! | C16: =#REF! -> #REF! | D16: =#REF! -> #REF! | E16: =#REF! -> #REF! | F16: =#REF! -> #REF! | G16: =#REF! -> #REF! | H16: =#REF! -> #REF! | I16: =#REF! -> #REF! | ... AD16: =#REF! -> #REF! | AF16: =#REF! -> #REF! | AG16: =#REF! -> #REF! | AH16: =#REF! -> #REF! | AI16: =#REF! -> #REF! | AJ16: =#REF! -> #REF! | AK16: =#REF! -> #REF!
A17: 13 | B17: =#REF! -> #REF! | C17: =#REF! -> #REF! | D17: =#REF! -> #REF! | E17: =#REF! -> #REF! | F17: =#REF! -> #REF! | G17: =#REF! -> #REF! | H17: =#REF! -> #REF! | I17: =#REF! -> #REF! | ... AD17: =#REF! -> #REF! | AF17: =#REF! -> #REF! | AG17: =#REF! -> #REF! | AH17: =#REF! -> #REF! | AI17: =#REF! -> #REF! | AJ17: =#REF! -> #REF! | AK17: =#REF! -> #REF!
... A39: 35 | B39: =#REF! -> #REF! | C39: =#REF! -> #REF! | D39: =#REF! -> #REF! | E39: =#REF! -> #REF! | F39: =#REF! -> #REF! | G39: =#REF! -> #REF! | H39: =#REF! -> #REF! | I39: =#REF! -> #REF! | ... AD39: =#REF! -> #REF! | AF39: =#REF! -> #REF! | AG39: =#REF! -> #REF! | AH39: =#REF! -> #REF! | AI39: =#REF! -> #REF! | AJ39: =#REF! -> #REF! | AK39: =#REF! -> #REF!
A40: 36 | B40: dr. Mochamad Faisal Bayu Pratomo | G40: =#REF! -> #REF! | H40: =#REF! -> #REF! | I40: =#REF! -> #REF! | J40: =#REF! -> #REF! | K40: =#REF! -> #REF! | L40: =#REF! -> #REF! | M40: =#REF! -> #REF! | N40: =#REF! -> #REF! | ... AD40: =#REF! -> #REF! | AF40: =#REF! -> #REF! | AG40: =#REF! -> #REF! | AH40: =#REF! -> #REF! | AI40: =#REF! -> #REF! | AJ40: =#REF! -> #REF! | AK40: =#REF! -> #REF!
A41: 37 | B41: =#REF! -> #REF! | C41: =#REF! -> #REF! | D41: =#REF! -> #REF! | E41: =#REF! -> #REF! | F41: =#REF! -> #REF! | G41: =#REF! -> #REF! | H41: =#REF! -> #REF! | I41: =#REF! -> #REF! | ... AD41: =#REF! -> #REF! | AF41: =#REF! -> #REF! | AG41: =#REF! -> #REF! | AH41: =#REF! -> #REF! | AI41: =#REF! -> #REF! | AJ41: =#REF! -> #REF! | AK41: =#REF! -> #REF!
A42: 38 | B42: =#REF! -> #REF! | C42: =#REF! -> #REF! | D42: =#REF! -> #REF! | E42: =#REF! -> #REF! | F42: =#REF! -> #REF! | G42: =#REF! -> #REF! | H42: =#REF! -> #REF! | I42: =#REF! -> #REF! | ... AD42: =#REF! -> #REF! | AF42: =#REF! -> #REF! | AG42: =#REF! -> #REF! | AH42: =#REF! -> #REF! | AI42: =#REF! -> #REF! | AJ42: =#REF! -> #REF! | AK42: =#REF! -> #REF!
A43: 39 | B43: =#REF! -> #REF! | C43: =#REF! -> #REF! | D43: =#REF! -> #REF! | E43: =#REF! -> #REF! | F43: =#REF! -> #REF! | G43: =#REF! -> #REF! | H43: =#REF! -> #REF! | I43: =#REF! -> #REF! | ... AD43: =#REF! -> #REF! | AF43: =#REF! -> #REF! | AG43: =#REF! -> #REF! | AH43: =#REF! -> #REF! | AI43: =#REF! -> #REF! | AJ43: =#REF! -> #REF! | AK43: =#REF! -> #REF!
A44: 40 | B44: =#REF! -> #REF! | C44: =#REF! -> #REF! | D44: =#REF! -> #REF! | E44: =#REF! -> #REF! | F44: =#REF! -> #REF! | G44: =#REF! -> #REF! | H44: =#REF! -> #REF! | I44: =#REF! -> #REF! | ... AD44: =#REF! -> #REF! | AF44: =#REF! -> #REF! | AG44: =#REF! -> #REF! | AH44: =#REF! -> #REF! | AI44: =#REF! -> #REF! | AJ44: =#REF! -> #REF! | AK44: =#REF! -> #REF!
A45: 41 | B45: =#REF! -> #REF! | C45: =#REF! -> #REF! | D45: =#REF! -> #REF! | E45: =#REF! -> #REF! | F45: =#REF! -> #REF! | G45: =#REF! -> #REF! | H45: =#REF! -> #REF! | I45: =#REF! -> #REF! | ... AD45: =#REF! -> #REF! | AF45: =#REF! -> #REF! | AG45: =#REF! -> #REF! | AH45: =#REF! -> #REF! | AI45: =#REF! -> #REF! | AJ45: =#REF! -> #REF! | AK45: =#REF! -> #REF!
A46: 42 | B46: =#REF! -> #REF! | C46: =#REF! -> #REF! | D46: =#REF! -> #REF! | E46: =#REF! -> #REF! | F46: =#REF! -> #REF! | G46: =#REF! -> #REF! | H46: =#REF! -> #REF! | I46: =#REF! -> #REF! | ... AD46: =#REF! -> #REF! | AF46: =#REF! -> #REF! | AG46: =#REF! -> #REF! | AH46: =#REF! -> #REF! | AI46: =#REF! -> #REF! | AJ46: =#REF! -> #REF! | AK46: =#REF! -> #REF!
A47: 43 | B47: =#REF! -> #REF! | C47: =#REF! -> #REF! | D47: =#REF! -> #REF! | E47: =#REF! -> #REF! | F47: =#REF! -> #REF! | G47: =#REF! -> #REF! | H47: =#REF! -> #REF! | I47: =#REF! -> #REF! | ... AD47: =#REF! -> #REF! | AF47: =#REF! -> #REF! | AG47: =#REF! -> #REF! | AH47: =#REF! -> #REF! | AI47: =#REF! -> #REF! | AJ47: =#REF! -> #REF! | AK47: =#REF! -> #REF!
A48: 44 | B48: =#REF! -> #REF! | C48: =#REF! -> #REF! | D48: =#REF! -> #REF! | E48: =#REF! -> #REF! | F48: =#REF! -> #REF! | G48: =#REF! -> #REF! | H48: =#REF! -> #REF! | I48: =#REF! -> #REF! | ... AD48: =#REF! -> #REF! | AF48: =#REF! -> #REF! | AG48: =#REF! -> #REF! | AH48: =#REF! -> #REF! | AI48: =#REF! -> #REF! | AJ48: =#REF! -> #REF! | AK48: =#REF! -> #REF!
A49: 45 | B49: =#REF! -> #REF! | C49: =#REF! -> #REF! | D49: =#REF! -> #REF! | E49: =#REF! -> #REF! | F49: =#REF! -> #REF! | G49: =#REF! -> #REF! | I49: =#REF! -> #REF! | K49: =#REF! -> #REF! | M49: =#REF! -> #REF! | O49: =#REF! -> #REF! | Q49: =#REF! -> #REF! | S49: =#REF! -> #REF! | U49: =#REF! -> #REF! | W49: =#REF! -> #REF! | Y49: =#REF! -> #REF! | Z49: =#REF! -> #REF! | AA49: =#REF! -> #REF! | AB49: =#REF! -> #REF! | AC49: =#REF! -> #REF! | AD49: =#REF! -> #REF! | AF49: =#REF! -> #REF! | AG49: =#REF! -> #REF! | AH49: =#REF! -> #REF! | AI49: =#REF! -> #REF! | AJ49: =#REF! -> #REF! | AK49: =#REF! -> #REF!
A50: 46 | B50: =#REF! -> #REF! | C50: =#REF! -> #REF! | D50: =#REF! -> #REF! | E50: =#REF! -> #REF! | F50: =#REF! -> #REF! | G50: =#REF! -> #REF! | H50: =#REF! -> #REF! | I50: =#REF! -> #REF! | ... AD50: =#REF! -> #REF! | AF50: =#REF! -> #REF! | AG50: =#REF! -> #REF! | AH50: =#REF! -> #REF! | AI50: =#REF! -> #REF! | AJ50: =#REF! -> #REF! | AK50: =#REF! -> #REF!
A51: 47 | B51: =#REF! -> #REF! | C51: =#REF! -> #REF! | D51: =#REF! -> #REF! | E51: =#REF! -> #REF! | F51: =#REF! -> #REF! | G51: =#REF! -> #REF! | H51: =#REF! -> #REF! | I51: =#REF! -> #REF! | ... AD51: =#REF! -> #REF! | AF51: =#REF! -> #REF! | AG51: =#REF! -> #REF! | AH51: =#REF! -> #REF! | AI51: =#REF! -> #REF! | AJ51: =#REF! -> #REF! | AK51: =#REF! -> #REF!
A52: 48 | B52: =#REF! -> #REF! | C52: =#REF! -> #REF! | D52: =#REF! -> #REF! | E52: =#REF! -> #REF! | F52: =#REF! -> #REF! | G52: =#REF! -> #REF! | H52: =#REF! -> #REF! | I52: =#REF! -> #REF! | ... AD52: =#REF! -> #REF! | AF52: =#REF! -> #REF! | AG52: =#REF! -> #REF! | AH52: =#REF! -> #REF! | AI52: =#REF! -> #REF! | AJ52: =#REF! -> #REF! | AK52: =#REF! -> #REF!
A53: 49 | B53: =#REF! -> #REF! | C53: =#REF! -> #REF! | D53: =#REF! -> #REF! | E53: =#REF! -> #REF! | F53: =#REF! -> #REF! | G53: =#REF! -> #REF! | H53: =#REF! -> #REF! | I53: =#REF! -> #REF! | ... AD53: =#REF! -> #REF! | AF53: =#REF! -> #REF! | AG53: =#REF! -> #REF! | AH53: =#REF! -> #REF! | AI53: =#REF! -> #REF! | AJ53: =#REF! -> #REF! | AK53: =#REF! -> #REF!
A54: 50 | B54: =#REF! -> #REF! | C54: =#REF! -> #REF! | D54: =#REF! -> #REF! | E54: =#REF! -> #REF! | F54: =#REF! -> #REF! | G54: =#REF! -> #REF! | H54: =#REF! -> #REF! | I54: =#REF! -> #REF! | ... AD54: =#REF! -> #REF! | AF54: =#REF! -> #REF! | AG54: =#REF! -> #REF! | AH54: =#REF! -> #REF! | AI54: =#REF! -> #REF! | AJ54: =#REF! -> #REF! | AK54: =#REF! -> #REF!
A55: 51 | B55: =#REF! -> #REF! | C55: =#REF! -> #REF! | D55: =#REF! -> #REF! | E55: =#REF! -> #REF! | F55: =#REF! -> #REF! | G55: =#REF! -> #REF! | H55: =#REF! -> #REF! | I55: =#REF! -> #REF! | ... AD55: =#REF! -> #REF! | AF55: =#REF! -> #REF! | AG55: =#REF! -> #REF! | AH55: =#REF! -> #REF! | AI55: =#REF! -> #REF! | AJ55: =#REF! -> #REF! | AK55: =#REF! -> #REF!
B56: =#REF! -> #REF! | C56: =#REF! -> #REF! | D56: =#REF! -> #REF! | E56: =#REF! -> #REF! | F56: =#REF! -> #REF! | G56: =#REF! -> #REF! | I56: =#REF! -> #REF! | K56: =#REF! -> #REF! | M56: =#REF! -> #REF! | O56: =#REF! -> #REF! | Q56: =#REF! -> #REF! | S56: =#REF! -> #REF! | U56: =#REF! -> #REF! | W56: =#REF! -> #REF! | Y56: =#REF! -> #REF! | AA56: =#REF! -> #REF! | AC56: =#REF! -> #REF!
G57: =#REF! -> #REF! | I57: =#REF! -> #REF! | K57: =#REF! -> #REF! | M57: =#REF! -> #REF! | O57: =#REF! -> #REF! | Q57: =#REF! -> #REF! | S57: =#REF! -> #REF! | U57: =#REF! -> #REF! | W57: =#REF! -> #REF! | Y57: =#REF! -> #REF! | AA57: =#REF! -> #REF! | AC57: =#REF! -> #REF!
G58: =#REF! -> #REF! | I58: =#REF! -> #REF! | K58: =#REF! -> #REF! | M58: =#REF! -> #REF! | O58: =#REF! -> #REF! | Q58: =#REF! -> #REF! | S58: =#REF! -> #REF! | U58: =#REF! -> #REF! | W58: =#REF! -> #REF! | Y58: =#REF! -> #REF! | AA58: =#REF! -> #REF! | AC58: =#REF! -> #REF!
G59: =#REF! -> #REF! | I59: =#REF! -> #REF! | K59: =#REF! -> #REF! | O59: =#REF! -> #REF! | Q59: =#REF! -> #REF! | S59: =#REF! -> #REF! | U59: =#REF! -> #REF! | W59: =#REF! -> #REF! | Y59: =#REF! -> #REF! | AA59: =#REF! -> #REF! | AC59: =#REF! -> #REF!
